{
 "cells": [
  {
   "attachments": {},
   "cell_type": "markdown",
   "metadata": {},
   "source": [
    "# Errors and Exception Handling\n",
    "\n"
   ]
  },
  {
   "cell_type": "code",
   "execution_count": 1,
   "metadata": {},
   "outputs": [
    {
     "ename": "SyntaxError",
     "evalue": "unterminated string literal (detected at line 1) (1679058590.py, line 1)",
     "output_type": "error",
     "traceback": [
      "\u001b[1;36m  Cell \u001b[1;32mIn[1], line 1\u001b[1;36m\u001b[0m\n\u001b[1;33m    print('Hello)\u001b[0m\n\u001b[1;37m          ^\u001b[0m\n\u001b[1;31mSyntaxError\u001b[0m\u001b[1;31m:\u001b[0m unterminated string literal (detected at line 1)\n"
     ]
    }
   ],
   "source": [
    "print('Hello)"
   ]
  },
  {
   "attachments": {},
   "cell_type": "markdown",
   "metadata": {},
   "source": [
    "Note how we get a SyntaxError, with the further description that it was an EOL (End of Line Error) while scanning the string literal. This is specific enough for us to see that we forgot a single quote at the end of the line. Understanding these various error types will help you debug your code much faster. \n",
    "\n",
    "This type of error and description is known as an Exception. Even if a statement or expression is syntactically correct, it may cause an error when an attempt is made to execute it. Errors detected during execution are called exceptions and are not unconditionally fatal.\n",
    "\n",
    "You can check out the full list of built-in exceptions [here](https://docs.python.org/3/library/exceptions.html). "
   ]
  },
  {
   "attachments": {},
   "cell_type": "markdown",
   "metadata": {},
   "source": [
    "## try and except\n",
    "\n",
    "The basic terminology and syntax used to handle errors in Python are the <code>try</code> and <code>except</code> statements. The code which can cause an exception to occur is put in the <code>try</code> block and the handling of the exception is then implemented in the <code>except</code> block of code. The syntax follows:\n",
    "\n",
    "    try:\n",
    "       You do your operations here...\n",
    "       ...\n",
    "    except ExceptionI:\n",
    "       If there is ExceptionI, then execute this block.\n",
    "    except ExceptionII:\n",
    "       If there is ExceptionII, then execute this block.\n",
    "       ...\n",
    "    else:\n",
    "       If there is no exception then execute this block. \n"
   ]
  },
  {
   "cell_type": "code",
   "execution_count": 1,
   "metadata": {},
   "outputs": [
    {
     "ename": "FileNotFoundError",
     "evalue": "[Errno 2] No such file or directory: 'testfile.txt'",
     "output_type": "error",
     "traceback": [
      "\u001b[1;31m---------------------------------------------------------------------------\u001b[0m",
      "\u001b[1;31mFileNotFoundError\u001b[0m                         Traceback (most recent call last)",
      "Cell \u001b[1;32mIn[1], line 1\u001b[0m\n\u001b[1;32m----> 1\u001b[0m f \u001b[38;5;241m=\u001b[39m \u001b[38;5;28;43mopen\u001b[39;49m\u001b[43m(\u001b[49m\u001b[38;5;124;43m'\u001b[39;49m\u001b[38;5;124;43mtestfile.txt\u001b[39;49m\u001b[38;5;124;43m'\u001b[39;49m\u001b[43m,\u001b[49m\u001b[38;5;124;43m'\u001b[39;49m\u001b[38;5;124;43mr\u001b[39;49m\u001b[38;5;124;43m'\u001b[39;49m\u001b[43m)\u001b[49m\n",
      "File \u001b[1;32mc:\\Users\\hariharan.sivakumar\\AppData\\Local\\anaconda3\\lib\\site-packages\\IPython\\core\\interactiveshell.py:282\u001b[0m, in \u001b[0;36m_modified_open\u001b[1;34m(file, *args, **kwargs)\u001b[0m\n\u001b[0;32m    275\u001b[0m \u001b[38;5;28;01mif\u001b[39;00m file \u001b[38;5;129;01min\u001b[39;00m {\u001b[38;5;241m0\u001b[39m, \u001b[38;5;241m1\u001b[39m, \u001b[38;5;241m2\u001b[39m}:\n\u001b[0;32m    276\u001b[0m     \u001b[38;5;28;01mraise\u001b[39;00m \u001b[38;5;167;01mValueError\u001b[39;00m(\n\u001b[0;32m    277\u001b[0m         \u001b[38;5;124mf\u001b[39m\u001b[38;5;124m\"\u001b[39m\u001b[38;5;124mIPython won\u001b[39m\u001b[38;5;124m'\u001b[39m\u001b[38;5;124mt let you open fd=\u001b[39m\u001b[38;5;132;01m{\u001b[39;00mfile\u001b[38;5;132;01m}\u001b[39;00m\u001b[38;5;124m by default \u001b[39m\u001b[38;5;124m\"\u001b[39m\n\u001b[0;32m    278\u001b[0m         \u001b[38;5;124m\"\u001b[39m\u001b[38;5;124mas it is likely to crash IPython. If you know what you are doing, \u001b[39m\u001b[38;5;124m\"\u001b[39m\n\u001b[0;32m    279\u001b[0m         \u001b[38;5;124m\"\u001b[39m\u001b[38;5;124myou can use builtins\u001b[39m\u001b[38;5;124m'\u001b[39m\u001b[38;5;124m open.\u001b[39m\u001b[38;5;124m\"\u001b[39m\n\u001b[0;32m    280\u001b[0m     )\n\u001b[1;32m--> 282\u001b[0m \u001b[38;5;28;01mreturn\u001b[39;00m io_open(file, \u001b[38;5;241m*\u001b[39margs, \u001b[38;5;241m*\u001b[39m\u001b[38;5;241m*\u001b[39mkwargs)\n",
      "\u001b[1;31mFileNotFoundError\u001b[0m: [Errno 2] No such file or directory: 'testfile.txt'"
     ]
    }
   ],
   "source": [
    "f = open('testfile.txt','r')    "
   ]
  },
  {
   "attachments": {},
   "cell_type": "markdown",
   "metadata": {},
   "source": [
    "Now let's see what would happen if we did not have write permission (opening only with 'r'):"
   ]
  },
  {
   "cell_type": "code",
   "execution_count": 3,
   "metadata": {},
   "outputs": [
    {
     "name": "stdout",
     "output_type": "stream",
     "text": [
      "Error: Could not find file or read data\n"
     ]
    }
   ],
   "source": [
    "try:\n",
    "    f = open('testfile','r')\n",
    "    f.write('Test write this')\n",
    "except IOError:\n",
    "    # This will only check for an IOError exception and then execute this print statement\n",
    "    print(\"Error: Could not find file or read data\")\n",
    "else:\n",
    "    print(\"Content written successfully\")\n",
    "    f.close()"
   ]
  },
  {
   "attachments": {},
   "cell_type": "markdown",
   "metadata": {},
   "source": [
    "The code still ran and we were able to continue doing actions and running code blocks. This is extremely useful when you have to account for possible input errors in your code. You can be prepared for the error and keep running code, instead of your code just breaking as we saw above.\n",
    "\n",
    "We could have also just said <code>except:</code> if we weren't sure what exception would occur. For example:"
   ]
  },
  {
   "cell_type": "code",
   "execution_count": 4,
   "metadata": {},
   "outputs": [
    {
     "name": "stdout",
     "output_type": "stream",
     "text": [
      "Error: Could not find file or read data\n"
     ]
    }
   ],
   "source": [
    "try:\n",
    "    f = open('testfile','r')\n",
    "    f.write('Test write this')\n",
    "except:\n",
    "    # This will check for any exception and then execute this print statement\n",
    "    print(\"Error: Could not find file or read data\")\n",
    "\n",
    "else:\n",
    "    print(\"Content written successfully\")\n",
    "    f.close()"
   ]
  },
  {
   "attachments": {},
   "cell_type": "markdown",
   "metadata": {},
   "source": [
    "we don't actually need to memorize that list of exception types! Now what if we kept wanting to run code after the exception occurred? This is where <code>finally</code> comes in.\n",
    "## finally\n",
    "The <code>finally:</code> block of code will always be run regardless if there was an exception in the <code>try</code> code block. The syntax is:\n",
    "\n",
    "    try:\n",
    "       Code block here\n",
    "       ...\n",
    "       Due to any exception, this code may be skipped!\n",
    "    finally:\n",
    "       This code block would always be executed.\n",
    "\n",
    "For example:"
   ]
  },
  {
   "cell_type": "code",
   "execution_count": 5,
   "metadata": {},
   "outputs": [
    {
     "name": "stdout",
     "output_type": "stream",
     "text": [
      "Always execute finally code blocks\n"
     ]
    }
   ],
   "source": [
    "try:\n",
    "    f = open(\"testfile\", \"w\")\n",
    "    f.write(\"Test write statement\")\n",
    "    f.close()\n",
    "finally:\n",
    "    print(\"Always execute finally code blocks\")"
   ]
  },
  {
   "attachments": {},
   "cell_type": "markdown",
   "metadata": {},
   "source": [
    "We can use this in conjunction with <code>except</code>. Let's see a new example that will take into account a user providing the wrong input:"
   ]
  },
  {
   "cell_type": "code",
   "execution_count": 4,
   "metadata": {
    "collapsed": true
   },
   "outputs": [
    {
     "name": "stdout",
     "output_type": "stream",
     "text": [
      "Finally, I executed!\n",
      "5\n"
     ]
    }
   ],
   "source": [
    "def askint():\n",
    "    try:\n",
    "        val = int(input(\"Please enter an integer: \"))\n",
    "    except:\n",
    "        print(\"Looks like you did not enter an integer!\")\n",
    "\n",
    "    finally:\n",
    "        print(\"Finally, I executed!\")\n",
    "    print(val)\n",
    "\n",
    "askint()"
   ]
  },
  {
   "cell_type": "code",
   "execution_count": 14,
   "metadata": {},
   "outputs": [
    {
     "name": "stdout",
     "output_type": "stream",
     "text": [
      "Looks like you did not enter an integer!\n",
      "I will always get executed\n"
     ]
    }
   ],
   "source": [
    "\n",
    "try:\n",
    "    val_1 = int(input(\"Please 1st enter an integer: \"))\n",
    "    val_2 = int(input(\"Please 2nd enter an integer: \"))\n",
    "    result = val_1/val_2\n",
    "    print(\"Result: \",result)\n",
    "except ValueError:\n",
    "    print(\"Looks like you did not enter an integer!\")\n",
    "except ZeroDivisionError:\n",
    "    print(\"Give value other than 0\")\n",
    "except:\n",
    "    print(\"No idea about the error\")\n",
    "else:\n",
    "    print(\"No exceptions detected\")\n",
    "finally:\n",
    "    print(\"I will always get executed\")"
   ]
  },
  {
   "cell_type": "code",
   "execution_count": 5,
   "metadata": {
    "collapsed": true
   },
   "outputs": [],
   "source": [
    "def askint():\n",
    "    try:\n",
    "        val = int(input(\"Please enter an integer: \"))\n",
    "    except:\n",
    "        print(\"Looks like you did not enter an integer!\")\n",
    "        val = int(input(\"Try again-Please enter an integer: \"))\n",
    "    finally:\n",
    "        print(\"Finally, I executed!\")\n",
    "    print(val)"
   ]
  },
  {
   "cell_type": "code",
   "execution_count": 6,
   "metadata": {},
   "outputs": [
    {
     "name": "stdout",
     "output_type": "stream",
     "text": [
      "Looks like you did not enter an integer!\n",
      "Finally, I executed!\n",
      "8\n"
     ]
    }
   ],
   "source": [
    "askint()"
   ]
  },
  {
   "attachments": {},
   "cell_type": "markdown",
   "metadata": {},
   "source": [
    "We can use a while loop!"
   ]
  },
  {
   "cell_type": "code",
   "execution_count": 23,
   "metadata": {
    "collapsed": true
   },
   "outputs": [],
   "source": [
    "def askint():\n",
    "    while True:\n",
    "        try:\n",
    "            val = int(input(\"Please enter an integer: \"))\n",
    "        except:\n",
    "            print(\"Looks like you did not enter an integer!\")\n",
    "            continue\n",
    "        else:\n",
    "            print(\"Yep that's an integer!\")\n",
    "            break\n",
    "        finally:     \n",
    "            print(\"Finally, I executed!\")\n",
    "        print(val)"
   ]
  },
  {
   "cell_type": "code",
   "execution_count": 25,
   "metadata": {},
   "outputs": [
    {
     "name": "stdout",
     "output_type": "stream",
     "text": [
      "Looks like you did not enter an integer!\n",
      "Finally, I executed!\n",
      "Yep that's an integer!\n",
      "Finally, I executed!\n"
     ]
    }
   ],
   "source": [
    "askint()"
   ]
  },
  {
   "attachments": {},
   "cell_type": "markdown",
   "metadata": {},
   "source": [
    "why did our function print \"Finally, I executed!\" after each trial, yet it never printed `val` itself? This is because with a try/except/finally clause, any <code>continue</code> or <code>break</code> statements are reserved until *after* the try clause is completed. This means that even though a successful input of **3** brought us to the <code>else:</code> block, and a <code>break</code> statement was thrown, the try clause continued through to <code>finally:</code> before breaking out of the while loop. And since <code>print(val)</code> was outside the try clause, the <code>break</code> statement prevented it from running.\n",
    "\n",
    "Let's make one final adjustment:"
   ]
  },
  {
   "cell_type": "code",
   "execution_count": 4,
   "metadata": {
    "collapsed": true
   },
   "outputs": [],
   "source": [
    "def askint():\n",
    "    while True:\n",
    "        try:\n",
    "            val = int(input(\"Please enter an integer: \"))\n",
    "        except:\n",
    "            print(\"Looks like you did not enter an integer!\")\n",
    "            continue\n",
    "        else:\n",
    "            print(\"Yep that's an integer!\")\n",
    "            print(val)\n",
    "            break\n",
    "        finally:\n",
    "            print(\"Finally, I executed!\")"
   ]
  },
  {
   "cell_type": "code",
   "execution_count": 5,
   "metadata": {},
   "outputs": [
    {
     "name": "stdout",
     "output_type": "stream",
     "text": [
      "Yep that's an integer!\n",
      "3\n",
      "Finally, I executed!\n"
     ]
    }
   ],
   "source": [
    "askint()"
   ]
  },
  {
   "cell_type": "markdown",
   "metadata": {},
   "source": [
    "# Defining Custom Exceptions "
   ]
  },
  {
   "cell_type": "markdown",
   "metadata": {},
   "source": [
    "In Python, custom exceptions allow you to define your own exception classes to handle specific error conditions in your code. This is particularly useful when you encounter situations that aren't adequately addressed by the built-in exceptions. Custom exceptions help make your code more modular and allow for clearer error handling. Here's an overview along with some examples:"
   ]
  },
  {
   "cell_type": "markdown",
   "metadata": {},
   "source": [
    "You can define a custom exception by creating a new class that inherits from the Exception base class or one of its subclasses. The naming convention for custom exceptions is to end the class name with \"Error\" to make it clear that it's an exception."
   ]
  },
  {
   "cell_type": "code",
   "execution_count": 2,
   "metadata": {},
   "outputs": [],
   "source": [
    "class CustomError(Exception):\n",
    "    pass\n"
   ]
  },
  {
   "cell_type": "markdown",
   "metadata": {},
   "source": [
    "# Example: Custom InputError\n",
    "\n",
    "Let's say you want to create a custom exception for handling invalid input. You can define an InputError class:"
   ]
  },
  {
   "cell_type": "code",
   "execution_count": 3,
   "metadata": {},
   "outputs": [],
   "source": [
    "class InputError(ValueError):\n",
    "    def __init__(self, message=\"Invalid input\"):\n",
    "        self.message = message\n",
    "        super().__init__(self.message)\n",
    "\n",
    "# Usage\n",
    "def process_input(value):\n",
    "    if not isinstance(value, int):\n",
    "        raise InputError(\"Input must be an integer\")\n",
    "    # Rest of the code processing valid input\n"
   ]
  },
  {
   "cell_type": "markdown",
   "metadata": {},
   "source": [
    "The super().__init__(self.message) line is used in a custom exception class to call the constructor of its parent class (usually Exception). It ensures that the basic initialization of the exception is done by the parent class, and the custom error message (self.message) is passed to it. This way, you get the standard behavior of the base class along with your specific customization for the custom exception."
   ]
  },
  {
   "cell_type": "markdown",
   "metadata": {},
   "source": [
    "Example: Custom FileError\n",
    "\n",
    "Suppose you want to create a custom exception for file-related errors:"
   ]
  },
  {
   "cell_type": "code",
   "execution_count": 5,
   "metadata": {},
   "outputs": [],
   "source": [
    "class FileError(Exception):\n",
    "    def __init__(self, filename, message=\"Error with file\"):\n",
    "        self.filename = filename\n",
    "        self.message = f\"{message}: {filename}\"\n",
    "        super().__init__(self.message)\n",
    "\n",
    "# Usage\n",
    "def read_file(file_path):\n",
    "    try:\n",
    "        with open(file_path, 'r') as file:\n",
    "            # Code for reading the file\n",
    "            pass\n",
    "    except FileNotFoundError:\n",
    "        raise FileError(file_path, \"File not found\")\n",
    "    except PermissionError:\n",
    "        raise FileError(file_path, \"Permission denied\")\n"
   ]
  },
  {
   "cell_type": "markdown",
   "metadata": {},
   "source": [
    "Benefits of Custom Exceptions\n",
    "\n",
    "Clarity: Custom exceptions provide meaningful names that convey the nature of the error, improving code readability.\n",
    "\n",
    "Modularity: They allow you to encapsulate error-handling logic in a separate class, promoting modular design.\n",
    "\n",
    "Specificity: Custom exceptions let you capture specific error conditions, making it easier to handle different scenarios appropriately.\n",
    "\n",
    "Consistency: Using custom exceptions ensures consistency in error handling throughout your codebase.\n",
    "\n",
    "Remember to raise custom exceptions when you encounter specific error conditions, and handle them appropriately in your code. This can lead to more robust and maintainable applications."
   ]
  },
  {
   "cell_type": "code",
   "execution_count": 7,
   "metadata": {},
   "outputs": [
    {
     "ename": "ValueError",
     "evalue": "invalid literal for int() with base 10: 'huoaha'",
     "output_type": "error",
     "traceback": [
      "\u001b[1;31m---------------------------------------------------------------------------\u001b[0m",
      "\u001b[1;31mValueError\u001b[0m                                Traceback (most recent call last)",
      "Cell \u001b[1;32mIn[7], line 1\u001b[0m\n\u001b[1;32m----> 1\u001b[0m a \u001b[38;5;241m=\u001b[39m  \u001b[38;5;28;43mint\u001b[39;49m\u001b[43m(\u001b[49m\u001b[38;5;28;43minput\u001b[39;49m\u001b[43m(\u001b[49m\u001b[38;5;124;43m\"\u001b[39;49m\u001b[38;5;124;43mEnter the number: \u001b[39;49m\u001b[38;5;124;43m\"\u001b[39;49m\u001b[43m)\u001b[49m\u001b[43m)\u001b[49m\n",
      "\u001b[1;31mValueError\u001b[0m: invalid literal for int() with base 10: 'huoaha'"
     ]
    }
   ],
   "source": []
  },
  {
   "cell_type": "code",
   "execution_count": 12,
   "metadata": {},
   "outputs": [
    {
     "name": "stdout",
     "output_type": "stream",
     "text": [
      "Something went wrong\n",
      "finally\n"
     ]
    }
   ],
   "source": [
    "try:\n",
    "    # a = int(input(\"enter the number\"))\n",
    "    # 4/0\n",
    "    # print(X\n",
    "    print(\"end\")\n",
    "except ValueError:\n",
    "    print(\"Entered wrong input\")\n",
    "except ZeroDivisionError:\n",
    "    print(\"zero division error\")\n",
    "except:\n",
    "    print(\"Something went wrong\")\n",
    "else:   \n",
    "    print(\"No exception detected\")\n",
    "finally:\n",
    "    print(\"finally\")"
   ]
  },
  {
   "cell_type": "code",
   "execution_count": null,
   "metadata": {},
   "outputs": [],
   "source": []
  }
 ],
 "metadata": {
  "kernelspec": {
   "display_name": "Python 3",
   "language": "python",
   "name": "python3"
  },
  "language_info": {
   "codemirror_mode": {
    "name": "ipython",
    "version": 3
   },
   "file_extension": ".py",
   "mimetype": "text/x-python",
   "name": "python",
   "nbconvert_exporter": "python",
   "pygments_lexer": "ipython3",
   "version": "3.11.3"
  }
 },
 "nbformat": 4,
 "nbformat_minor": 1
}
